Workbook
Name Acs: Constants!$B$30
Name Adc: Loop_Modeling!$B$34
Name Adc_ea: Loop_Modeling!$B$58
Name ADC_VINmin: Variable_Management!$B$178
Name Cac: Variable_Management!$B$132
Name Cac_min: Variable_Management!$B$131
Name CCOMP: Variable_Management!$B$238
Name CCOMP_Calc: Variable_Management!$B$237
Name CCOMP_calc_CCM: Variable_Management!$B$207
Name CCOMP_CALC_DCM: Variable_Management!$B$228
Name CHF: Variable_Management!$B$240
Name CHF_calc: Variable_Management!$B$239
Name CHF_CALC_CCM: Variable_Management!$B$208
Name CHF_CALC_DCM: Variable_Management!$B$229
Name Comp_calc_CCM: Variable_Management!$B$207
Name Cout: Variable_Management!$B$144
Name Cout_min: Variable_Management!$B$142
Name D_limit_max: Constants!$B$18
Name D_limit_min: Constants!$B$16
Name D_limit_nom: Constants!$B$17
Name DC_DCM_max: Variable_Management!$B$32
Name Dc_max_IC: Variable_Management!$B$20
Name Dc_max_ideal: Variable_Management!$A$19
Name DC_rip: Variable_Management!#REF!
Name Dc_rip_max: Variable_Management!#REF!
Name Dc_VIN_max: Variable_Management!$B$87
Name Dc_VIN_min: Variable_Management!$B$53
Name Dc_VIN_nom: Variable_Management!$B$70
Name DC_VIN_Var: Loop_Modeling!$B$18
Name DC_VIN_var_DCM: Loop_Modeling!$B$66
Name EFF_est: Variable_Management!$B$17
Name Eff_vs_IOUT: Plot_Management_Eff!$C$3
Name fcross: Variable_Management!$B$233
Name fcross_est: Variable_Management!$B$232
Name fp_ea_est: Variable_Management!$B$202
Name Fsw: Variable_Management!$B$10
Name fz_ea_est: Variable_Management!$B$201
Name fz_rhp: Variable_Management!$B$187
Name Gcomp: Constants!$B$29
Name Gea_mid_calc: Variable_Management!#REF!
Name gfs: Variable_Management!$B$256
Name gm_ea: Constants!$B$34
Name Gplant_fc_dB: Loop_Modeling!$AD$7
Name IIN_33: Variable_Management!#REF!
Name IL_coupled: Variable_Management!$B$24
Name IL_pk: Variable_Management!$B$122
Name IL_pk_max: Variable_Management!$B$123
Name ILA_avg_VIN_max: Variable_Management!$B$90
Name ILA_avg_VIN_min: Variable_Management!$B$56
Name ILA_avg_VIN_nom: Variable_Management!$B$73
Name ILAp_VINmax: Variable_Management!$B$92
Name ILAp_VINmin: Variable_Management!$B$58
Name ILAp_VINnom: Variable_Management!$B$75
Name ILArip_VINmax: Variable_Management!$B$91
Name ILArip_VINmin: Variable_Management!$B$57
Name ILArip_VINnom: Variable_Management!$B$74
Name ILB_avg_VIN_max: Variable_Management!$B$95
Name ILB_avg_VIN_min: Variable_Management!$B$61
Name ILB_avg_VIN_nom: Variable_Management!$B$78
Name ILBp_VIN_max: Variable_Management!$B$97

Sheet Design Converter
E1: LM3478-88 DC/DC Coupled Inductor SEPIC Controller Design Tool
A3: ABOUT | F3: =Input Box | O3: TERMS OF USE
O5: =CONCATENATE("Rev ",Licenses!$B$5) -> Rev 1.0.0 | P5: October-2024
A6: Step 1: Design Specifications
G7: Minimum Input Supply Voltage , VSUPPLY(min) | H7: 3 | I7: V
G8: Typical Input Supply Voltage, VSUPPLY(typ) | H8: 3.7 | I8: V
G9: Maximum Input Supply Voltage , VSUPPLY(max) | H9: =4.2*3 -> 12.6 | I9: V
G10: Output Target Voltage, VLOAD | H10: 10 | I10: V
G11: Maximum Output Current , ILOAD | H11: 2.5 | I11: A
G12: Free Running Switching Frequency, FSW | H12: 700 | I12: kHz
G13: Free running Oscillator Set Resistor, RT | H13: =RT/1000 -> 19.439201 | I13: kΩ
G14: Output Power, POUT | H14: =POUT -> 25 | I14: W
G15: Recommended maximum duty cycle LM3478-88 at VSUPPLY(MIN) | H15: =Dc_max_IC*100 -> 97 | I15: %
G16: Ideal Duty Cycle at VSUPPLY(MIN) | H16: =Variable_Management!B19*100 -> 76.923077 | I16: %
A18: Step 2: Filter Inductor
G19: Required Mode of Operation: | H19: =IF(Variable_Management!B21=0,"CCM","DCM") -> CCM
G20: Desired Maximum Inductor Current Ripple Ratio (IRR_MAX) | H20: 60 | I20: %
G21: Recommended Inductance (LM_CALC) | H21: =Variable_Management!B38*10^6 -> 0.47584289 | I21: uH
G22: User Selection. Inductance, (LM) | H22: 10 | I22: uH
G23: Peak inductor current, ILPK | H23: =ISW_peak_VIN_min -> 11.163004 | I23: A
A25: Step 3: Current Sense Resistor Selection
G26: Peak Current Limit Margin | H26: 30 | I26: %
G27: Selected Peak Current limit (ILSW_select) | H27: =Ipk_selected -> 14.511905 | I27: A
G28: Recommended current sense Resistor (RS) | H28: =Variable_Management!B115*1000 -> 10.749795 | I28: mΩ
G29: Recommended external slope compensation Resistor (RSL) | H29: =Variable_Management!B116 -> 0 | I29: Ω
G30: Selected current sense Resistor (RS) | H30: 10 | I30: mΩ
G31: Selected external slope compensation Resistor (RSL) | H31: 0 | I31: Ω
G32: Actual switch peak current limit | H32: =IL_pk_max -> 15.6 | I32: A
A34: Step 4: CAC Capacitor Selection
G35: Minimum couplpling capacitor value (CAC_min) | H35: =Cac_min*(10^6) -> 4.3607186 | I35: uF
G36: Selected Coupling Capacitor (CAC) | H36: 10 | I36: uF
G37: Minimuum require CAC RMS current Rating | H37: =Variable_Management!B134 -> 4.5643546 | I37: A
A39: Step 5: Output Capacitor Selection
G40: Desired load step ripple voltage (ΔvOUT) | H40: 500 | I40: mV
G41: Minimum output capacitance | H41: =Cout_min*10^6 -> 541.66667 | I41: uF
G42: Capacitor RMS current (IRMS_COUT) | H42: =IRMS_COUT -> 4.5643546 | I42: A
G43: Selected Output Capacitance (COUT) | H43: 560 | I43: uF
G44: Equivalent COUT ESR (RESR) | H44: 28 | I44: mΩ
Q53: =VIN_min -> 3
A58: Step 6: Loop Compensation
...

Sheet Licenses
A5: Version Number | B5: 1.0.0
A35: Version History
A36: Version | B36: Change List Description
A37: 1.0.0 | B37: Initial Release

Sheet Variable_Management
A1: EXCEL Variables Names/Calculations
B2: Input from user =
B3: Output = | F3: Base Calculations of | G3: Spec conditions | H3: Nominal right now
B4: Constant
A5: Variable Name | B5: Value | C5: STD Units | E5: Notes | J5: Iteration | K5: Flag
A6: Step 1: Operational Specs
A7: VIN_min | B7: ='Design Converter'!H7 -> 3 | C7: V | E7: Minimum input voltage
A8: VIN_nom | B8: ='Design Converter'!H8 -> 3.7 | C8: V | E8: Nominal input voltage | K8: =IF(VIN_min<VIN_min,1,IF(VIN_nom>VIN_max,1,0)) -> 0
A9: VIN_max | B9: ='Design Converter'!H9 -> 12.6 | C9: V | E9: Maximum input voltage
A10: Fsw | B10: ='Design Converter'!H12*1000 -> 700000 | C10: Hz | E10: Switching frequnecy
A11: RT | B11: =(4.503*10^11)*Fsw^-1.26 -> 19439.201 | C11: Ω | E11: Oscillator Set resistor. Based on the datasheet equation
A13: VOUT | B13: ='Design Converter'!H10 -> 10 | C13: V | E13: Target Output Voltage
A14: IOUT | B14: ='Design Converter'!H11 -> 2.5 | C14: A | E14: Maximum Output current
A15: ROUT | B15: =VOUT/IOUT -> 4 | C15: Ω | E15: Minimum load resistance
A16: POUT | B16: =VOUT*IOUT -> 25 | C16: W | E16: Total output power
A17: EFF_est | B17: 1 | E17: Estimated efficiency. Assuming 95% to give some margin
A19: Dc_max_ideal | B19: =(VOUT)/(VIN_min+VOUT) -> 0.76923077 | E19: Maximum duty cycle at the minimum input voltage. Includes estimated efficiency for margin
A20: Dc_max_IC | B20: =Constants!B20 -> 0.97 | E20: Maximum IC duty cycle. Based on the forced off time. See Mathcad Calculations
A21: DCM_Flag | B21: =IF(B19>Dc_max_IC,1,0) -> 0 | E21: Is discontinuous conduction mode required to achieve step up ratio? | K21: =B21 -> 0
E22: *Note right now DCM is not active for SEPIC calculations
A24: IL_coupled | B24: 1 | E24: are the inductors coupled? (1 = Yes, 0 = No). This will be an option in future revisions
A26: Step 2: Filter Inductor
A27: CCM Operation calculations | E27: Calculate the inductor at nominal voltage. This should allow for the best efficiency
A28: ILrip | B28: ='Design Converter'!H20/100 -> 0.6 | E28: Selected indutor ripple ratio. Will be changed later to a standard value just to keep things simple
A29: Lopt_2 | B29: =(VIN_nom^2)/(2*ILrip*IOUT*Fsw*(VIN_nom+VOUT)) -> 4.7584289e-07 | C29: H | E29: This value used to make the selection for CCM calculations. This is done at the Nominal input voltage
A31: DCM Strategy | E31: "Currently this is set of a boost Converter. Will need to change when Supporting DCM Calculation
A32: DC_DCM_max | B32: 0.7 | E32: Maximum duty cycle for DCM operation. 70% is a good starting point. Could be related to the switching frequency
A33: L_DCM_DC | B33: =((DC_DCM_max^2)*(VIN_min^2))/(2*IOUT*VOUT*Fsw-2*IOUT*VIN_min*Fsw) -> 1.8e-07 | C33: H | E33: Select DCM duty cycle to be 70%. This will keep the ripple current fairly low and allow for efficiency drops.
A34: M_L_DCM | B34: 0.2 | E34: Margin to allow for inductor ripple current to be greater than the average input current
A35: L_DCM_M | B35: =(1-M_L_DCM)*((VIN_min^2)*(1-(VIN_min/VOUT)))/(2*IOUT*VOUT*Fsw) -> 1.44e-07 | C35: H | E35: Inductor value that ensures the ripple current is larger than the average input current
A36: L_DCM | B36: =MIN(B33,B35) -> 1.44e-07 | C36: H | E36: Select the lowest of the two inductor value calculations
A38: Lm_calc | B38: =IF(B21=1,B36,Lopt_2) -> 4.7584289e-07 | E38: If DCM is required (high step-up ratio) output L_DCM. Otherwise output the CCM inductor value
A40: Lm | B40: ='Design Converter'!H22*10^-6 -> 1e-05 | C40: H | E40: Selected filter inductor
B41: =Lm -> 1e-05 | E41: Input from user for uncoupled design
A42: Lm_A | B42: =Lm -> 1e-05 | E42: Input coil inductance
B43: =Lm -> 1e-05 | E43: Input from user for uncoupled design
A44: Lm_B | B44: =Lm -> 1e-05 | E44: Output coil inductance
A46: Rdcr | B46: =10*10^-3 -> 0.01 | C46: Ω | E46: Filter inductor DCR
A47: Ltol | B47: 0.2 | E47: Assumed inductor tolerance. Constant to help simplify the user experience
B48: .
...

Sheet Eff_vs_IOUT
A1: EXCEL Variables Names/Calculations
Y2: Coils are not included in the efficiency calculations
R5: Operation Variables | V5: Duty Cycle | Y5: Inductor (Written of the switch on SEPIC) | AE5: MOSFET | AJ5: Diode | AO5: Other Losses | AR5: Total Losses
R6: VOUT | S6: IOUT | T6: VIN | U6: IIN | V6: DCM/CCM | W6: DC | X6: DC_off | Y6: dIL | Z6: ILPEAK | AA6: ILRMS | AB6: PLac (W) | AC6: PL_DCR (W) | AD6: PL_tot (W) | AE6: ISWAVG (A) | AF6: ISWRMS | AG6: PQ_COND (W) | AH6: PQ_SW (W) | AI6: PQ_tot (W) | AJ6: IDAVG (A) | AK6: IDRMS | AL6: PD_COND (W) | AM6: PD_SW (W) | AN6: PD_tot (W) | AO6: PRCS (W) | AP6: PG_drv (W) | AQ6: PIQ (W) | AR6: PTOTAL (W) | AS6: POUT (W) | AT6: Eff
Q7: 0 | R7: =VOUT -> 10 | S7: =Q7*$O$12 -> 0 | T7: =VIN_var -> 4 | U7: =(R7*S7)/(T7*EFF_est) -> 0 | V7: =IF(S7<((T7^2)*R7)/(2*Fsw*Lm*((T7+R7)^2)),1,2) -> 1 | W7: =CHOOSE(V7,SQRT(2*Lm*R7*S7*Fsw)/T7,R7/(T7+R7)) -> 0 | X7: =CHOOSE(V7,(Lm*Z7*Fsw)/(R7),1-W7) -> 0 | Y7: =(T7*W7)/(Lm*Fsw) -> 0 | Z7: =U7+S7+(Y7) -> 0 | AA7: =CHOOSE(V7,Z7*SQRT((W7+X7)/3),SQRT((U7^2)+((Y7^2)/12))) -> 0 | AB7: 0 | AC7: =(AA7^2)*Rdcr -> 0 | AD7: =AB7+AC7 -> 0 | AE7: =U7*S7*W7 -> 0 | AF7: =AA7 -> 0 | AG7: =(AF7^2)*RDS_on -> 0 | AH7: =(((R7+T7)*(U7+S7))/2)*Fsw*(tr_sw+tf_sw) -> 0 | AI7: =AG7+AH7 -> 0 | AJ7: =S7 -> 0 | AK7: =CHOOSE(V7,Z7*SQRT(X7/3),SQRT(X7*((Z7^2)+((Y7^2)/3)-(Y7*Z7)))) -> 0 | AL7: =S7*Vd_rect -> 0 | AM7: =(R7+T7+Vd_rect)*Qrr*Fsw -> 0 | AN7: =AL7+AM7 -> 0 | AO7: =(AF7^2)*R_cs -> 0 | AP7: =Qg_tot*Vcc*Fsw -> 0.1512 | AQ7: =IQ*T7 -> 0.0132 | AR7: =AO7+AN7+AI7+AP7+AQ7 -> 0.1644 | AS7: =R7*S7 -> 0 | AT7: =(AS7/(AS7+AR7))*100 -> 0
M8: =Fsw -> 700000 | Q8: 1 | R8: =VOUT -> 10 | S8: =Q8*$O$12 -> 0.016666667 | T8: =VIN_var -> 4 | U8: =(R8*S8)/(T8*EFF_est) -> 0.041666667 | V8: =IF(S8<((T8^2)*R8)/(2*Fsw*Lm*((T8+R8)^2)),1,2) -> 1 | W8: =CHOOSE(V8,SQRT(2*Lm*R8*S8*Fsw)/T8,R8/(T8+R8)) -> 0.38188131 | X8: =CHOOSE(V8,(Lm*Z8*Fsw)/(R8),1-W8) -> 0.19358586 | Y8: =(T8*W8)/(Lm*Fsw) -> 0.21821789 | Z8: =U8+S8+(Y8) -> 0.27655122 | AA8: =CHOOSE(V8,Z8*SQRT((W8+X8)/3),SQRT((U8^2)+((Y8^2)/12))) -> 0.12112261 | AB8: 0 | AC8: =(AA8^2)*Rdcr -> 0.00014670687 | AD8: =AB8+AC8 -> 0.00014670687 | AE8: =U8*S8*W8 -> 0.00026519535 | AF8: =AA8 -> 0.12112261 | AG8: =(AF8^2)*RDS_on -> 9.5359468e-05 | AH8: =(((R8+T8)*(U8+S8))/2)*Fsw*(tr_sw+tf_sw) -> -0.001584401 | AI8: =AG8+AH8 -> -0.0014890416 | AJ8: =S8 -> 0.016666667 | AK8: =CHOOSE(V8,Z8*SQRT(X8/3),SQRT(X8*((Z8^2)+((Y8^2)/3)-(Y8*Z8)))) -> 0.07025088 | AL8: =S8*Vd_rect -> 0.0054166667 | AM8: =(R8+T8+Vd_rect)*Qrr*Fsw -> 0 | AN8: =AL8+AM8 -> 0.0054166667 | AO8: =(AF8^2)*R_cs -> 0.00014670687 | AP8: =Qg_tot*Vcc*Fsw -> 0.1512 | AQ8: =IQ*T8 -> 0.0132 | AR8: =AO8+AN8+AI8+AP8+AQ8 -> 0.16847433 | AS8: =R8*S8 -> 0.16666667 | AT8: =(AS8/(AS8+AR8))*100 -> 49.730313
N9: VIN_VAR | O9: =VIN_var -> 4 | P9: V | Q9: 2 | R9: =VOUT -> 10 | S9: =Q9*$O$12 -> 0.033333333 | T9: =VIN_var -> 4 | U9: =(R9*S9)/(T9*EFF_est) -> 0.083333333 | V9: =IF(S9<((T9^2)*R9)/(2*Fsw*Lm*((T9+R9)^2)),1,2) -> 1 | W9: =CHOOSE(V9,SQRT(2*Lm*R9*S9*Fsw)/T9,R9/(T9+R9)) -> 0.54006172 | X9: =CHOOSE(V9,(Lm*Z9*Fsw)/(R9),1-W9) -> 0.29769136 | Y9: =(T9*W9)/(Lm*Fsw) -> 0.3086067 | Z9: =U9+S9+(Y9) -> 0.42527337 | AA9: =CHOOSE(V9,Z9*SQRT((W9+X9)/3),SQRT((U9^2)+((Y9^2)/12))) -> 0.22473234 | AB9: 0 | AC9: =(AA9^2)*Rdcr -> 0.00050504625 | AD9: =AB9+AC9 -> 0.00050504625 | AE9: =U9*S9*W9 -> 0.0015001715 | AF9: =AA9 -> 0.22473234 | AG9: =(AF9^2)*RDS_on -> 0.00032828006 | AH9: =(((R9+T9)*(U9+S9))/2)*Fsw*(tr_sw+tf_sw) -> -0.003168802 | AI9: =AG9+AH9 -> -0.002840522 | AJ9: =S9 -> 0.033333333 | AK9: =CHOOSE(V9,Z9*SQRT(X9/3),SQRT(X9*((Z9^2)+((Y9^2)/3)-(Y9*Z9)))) -> 0.13396479 | AL9: =S9*Vd_rect -> 0.010833333 | AM9: =(R9+T9+Vd_rect)*Qrr*Fsw -> 0 | AN9: =AL9+AM9 -> 0.010833333 | AO9: =(AF9^2)*R_cs -> 0.00050504625 | AP9: =Qg_tot*Vcc*Fsw -> 0.1512 | AQ9: =IQ*T9 -> 0.0132 | AR9: =AO9+AN9+AI9+AP9+AQ9 -> 0.17289786 | AS9: =R9*S9 -> 0.33333333 | AT9: =(AS9/(AS9+AR9))*100 -> 65.846068
Q10: 3 | R10: =VOUT -> 10 | S10: =Q10*$O$12 -> 0.05 | T10: =VIN_var -> 4 | U10: =(R10*S10)/(T10*EFF_est) -> 0.125 | V10: =IF(S10<((T10^2)*R10)/(2*Fsw*Lm*((T10+R10)^2)),1,2) -> 1 | W10: =CHOOSE(V10,SQRT(2*Lm*R10*S10*Fsw)/T10,R10/(T10+R10)) -> 0.66143783 | X10: =CHOOSE(V10,(Lm*Z10*Fsw)/(R10),1-W10) -> 0.38707513 | Y10: =(T10*W10)/(Lm*Fsw) -> 0.37796447 | Z10: =U10+S10+(Y10) -> 0.55296447 | AA10: =CHOOSE(V10,Z10*SQRT((W10+X10)/3),SQRT((U10^2)+((Y10^2)/12))) -> 0.32690646 | AB10: 0 | AC10: =(AA10^2)*Rdcr -> 0.0010686783 | AD10: =AB10+AC10 -> 0.0010686783 | AE10: =U10*S10*W10 -> 0.0041339864 | AF10: =AA10 -> 0.32690646 | AG10: =(AF10^2)*RDS_on -> 0.00069464092 | AH10: =(((R10+T10)*(U10+S10))/2)*Fsw*(tr_sw+tf_sw) -> -0.0047532031 | AI10: =AG10+AH10 -> -0.0040585621 | AJ10: =S10 -> 0.05 | AK10: =CHOOSE(V10,Z10*SQRT(X10/3),SQRT(X10*((Z10^2)+((Y10^2)/3)-(Y10*Z10)))) -> 0.19862515 | AL10: =S10*Vd_rect -> 0.01625 | AM10: =(R10+T10+Vd_rect)*Qrr*Fsw -> 0 | AN10: =AL10+AM10 -> 0.01625 | AO10: =(AF10^2)*R_cs -> 0.0010686783 | AP10: =Qg_tot*Vcc*Fsw -> 0.1512 | AQ10: =IQ*T10 -> 0.0132 | AR10: =AO10+AN10+AI10+AP10+AQ10 -> 0.17766012 | AS10: =R10*S10 -> 0.5 | AT10: =(AS10/(AS10+AR10))*100 -> 73.783301
N11: Steps | O11: 150 | Q11: 4 | R11: =VOUT -> 10 | S11: =Q11*$O$12 -> 0.066666667 | T11: =VIN_var -> 4 | U11: =(R11*S11)/(T11*EFF_est) -> 0.16666667 | V11: =IF(S11<((T11^2)*R11)/(2*Fsw*Lm*((T11+R11)^2)),1,2) -> 2 | W11: =CHOOSE(V11,SQRT(2*Lm*R11*S11*Fsw)/T11,R11/(T11+R11)) -> 0.71428571 | X11: =CHOOSE(V11,(Lm*Z11*Fsw)/(R11),1-W11) -> 0.28571429 | Y11: =(T11*W11)/(Lm*Fsw) -> 0.40816327 | Z11: =U11+S11+(Y11) -> 0.6414966 | AA11: =CHOOSE(V11,Z11*SQRT((W11+X11)/3),SQRT((U11^2)+((Y11^2)/12))) -> 0.20410998 | AB11: 0 | AC11: =(AA11^2)*Rdcr -> 0.00041660882 | AD11: =AB11+AC11 -> 0.00041660882 | AE11: =U11*S11*W11 -> 0.0079365079 | AF11: =AA11 -> 0.20410998 | AG11: =(AF11^2)*RDS_on -> 0.00027079573 | AH11: =(((R11+T11)*(U11+S11))/2)*Fsw*(tr_sw+tf_sw) -> -0.0063376041 | AI11: =AG11+AH11 -> -0.0060668084 | AJ11: =S11 -> 0.066666667 | AK11: =CHOOSE(V11,Z11*SQRT(X11/3),SQRT(X11*((Z11^2)+((Y11^2)/3)-(Y11*Z11)))) -> 0.2421422 | AL11: =S11*Vd_rect -> 0.021666667 | AM11: =(R11+T11+Vd_rect)*Qrr*Fsw -> 0 | AN11: =AL11+AM11 -> 0.021666667 | AO11: =(AF11^2)*R_cs -> 0.00041660882 | AP11: =Qg_tot*Vcc*Fsw -> 0.1512 | AQ11: =IQ*T11 -> 0.0132 | AR11: =AO11+AN11+AI11+AP11+AQ11 -> 0.18041647 | AS11: =R11*S11 -> 0.66666667 | AT11: =(AS11/(AS11+AR11))*100 -> 78.701445
N12: Step size | O12: =IOUT/(O11) -> 0.016666667 | Q12: 5 | R12: =VOUT -> 10 | S12: =Q12*$O$12 -> 0.083333333 | T12: =VIN_var -> 4 | U12: =(R12*S12)/(T12*EFF_est) -> 0.20833333 | V12: =IF(S12<((T12^2)*R12)/(2*Fsw*Lm*((T12+R12)^2)),1,2) -> 2 | W12: =CHOOSE(V12,SQRT(2*Lm*R12*S12*Fsw)/T12,R12/(T12+R12)) -> 0.71428571 | X12: =CHOOSE(V12,(Lm*Z12*Fsw)/(R12),1-W12) -> 0.28571429 | Y12: =(T12*W12)/(Lm*Fsw) -> 0.40816327 | Z12: =U12+S12+(Y12) -> 0.69982993 | AA12: =CHOOSE(V12,Z12*SQRT((W12+X12)/3),SQRT((U12^2)+((Y12^2)/12))) -> 0.23934469 | AB12: 0 | AC12: =(AA12^2)*Rdcr -> 0.00057285882 | AD12: =AB12+AC12 -> 0.00057285882 | AE12: =U12*S12*W12 -> 0.012400794 | AF12: =AA12 -> 0.23934469 | AG12: =(AF12^2)*RDS_on -> 0.00037235823 | AH12: =(((R12+T12)*(U12+S12))/2)*Fsw*(tr_sw+tf_sw) -> -0.0079220051 | AI12: =AG12+AH12 -> -0.0075496469 | AJ12: =S12 -> 0.083333333 | AK12: =CHOOSE(V12,Z12*SQRT(X12/3),SQRT(X12*((Z12^2)+((Y12^2)/3)-(Y12*Z12)))) -> 0.27237027 | AL12: =S12*Vd_rect -> 0.027083333 | AM12: =(R12+T12+Vd_rect)*Qrr*Fsw -> 0 | AN12: =AL12+AM12 -> 0.027083333 | AO12: =(AF12^2)*R_cs -> 0.00057285882 | AP12: =Qg_tot*Vcc*Fsw -> 0.1512 | AQ12: =IQ*T12 -> 0.0132 | AR12: =AO12+AN12+AI12+AP12+AQ12 -> 0.18450655 | AS12: =R12*S12 -> 0.83333333 | AT12: =(AS12/(AS12+AR12))*100 -> 81.872734
Q13: 6 | R13: =VOUT -> 10 | S13: =Q13*$O$12 -> 0.1 | T13: =VIN_var -> 4 | U13: =(R13*S13)/(T13*EFF_est) -> 0.25 | V13: =IF(S13<((T13^2)*R13)/(2*Fsw*Lm*((T13+R13)^2)),1,2) -> 2 | W13: =CHOOSE(V13,SQRT(2*Lm*R13*S13*Fsw)/T13,R13/(T13+R13)) -> 0.71428571 | X13: =CHOOSE(V13,(Lm*Z13*Fsw)/(R13),1-W13) -> 0.28571429 | Y13: =(T13*W13)/(Lm*Fsw) -> 0.40816327 | Z13: =U13+S13+(Y13) -> 0.75816327 | AA13: =CHOOSE(V13,Z13*SQRT((W13+X13)/3),SQRT((U13^2)+((Y13^2)/12))) -> 0.27637493 | AB13: 0 | AC13: =(AA13^2)*Rdcr -> 0.00076383104 | AD13: =AB13+AC13 -> 0.00076383104 | AE13: =U13*S13*W13 -> 0.017857143 | AF13: =AA13 -> 0.27637493 | AG13: =(AF13^2)*RDS_on -> 0.00049649018 | AH13: =(((R13+T13)*(U13+S13))/2)*Fsw*(tr_sw+tf_sw) -> -0.0095064061 | AI13: =AG13+AH13 -> -0.009009916 | AJ13: =S13 -> 0.1 | AK13: =CHOOSE(V13,Z13*SQRT(X13/3),SQRT(X13*((Z13^2)+((Y13^2)/3)-(Y13*Z13)))) -> 0.30279156 | AL13: =S13*Vd_rect -> 0.0325 | AM13: =(R13+T13+Vd_rect)*Qrr*Fsw -> 0 | AN13: =AL13+AM13 -> 0.0325 | AO13: =(AF13^2)*R_cs -> 0.00076383104 | AP13: =Qg_tot*Vcc*Fsw -> 0.1512 | AQ13: =IQ*T13 -> 0.0132 | AR13: =AO13+AN13+AI13+AP13+AQ13 -> 0.18865392 | AS13: =R13*S13 -> 1 | AT13: =(AS13/(AS13+AR13))*100 -> 84.128777
Q14: 7 | R14: =VOUT -> 10 | S14: =Q14*$O$12 -> 0.11666667 | T14: =VIN_var -> 4 | U14: =(R14*S14)/(T14*EFF_est) -> 0.29166667 | V14: =IF(S14<((T14^2)*R14)/(2*Fsw*Lm*((T14+R14)^2)),1,2) -> 2 | W14: =CHOOSE(V14,SQRT(2*Lm*R14*S14*Fsw)/T14,R14/(T14+R14)) -> 0.71428571 | X14: =CHOOSE(V14,(Lm*Z14*Fsw)/(R14),1-W14) -> 0.28571429 | Y14: =(T14*W14)/(Lm*Fsw) -> 0.40816327 | Z14: =U14+S14+(Y14) -> 0.8164966 | AA14: =CHOOSE(V14,Z14*SQRT((W14+X14)/3),SQRT((U14^2)+((Y14^2)/12))) -> 0.31456724 | AB14: 0 | AC14: =(AA14^2)*Rdcr -> 0.00098952549 | AD14: =AB14+AC14 -> 0.00098952549 | AE14: =U14*S14*W14 -> 0.024305556 | AF14: =AA14 -> 0.31456724 | AG14: =(AF14^2)*RDS_on -> 0.00064319157 | AH14: =(((R14+T14)*(U14+S14))/2)*Fsw*(tr_sw+tf_sw) -> -0.011090807 | AI14: =AG14+AH14 -> -0.010447616 | AJ14: =S14 -> 0.11666667 | AK14: =CHOOSE(V14,Z14*SQRT(X14/3),SQRT(X14*((Z14^2)+((Y14^2)/3)-(Y14*Z14)))) -> 0.33335318 | AL14: =S14*Vd_rect -> 0.037916667 | AM14: =(R14+T14+Vd_rect)*Qrr*Fsw -> 0 | AN14: =AL14+AM14 -> 0.037916667 | AO14: =(AF14^2)*R_cs -> 0.00098952549 | AP14: =Qg_tot*Vcc*Fsw -> 0.1512 | AQ14: =IQ*T14 -> 0.0132 | AR14: =AO14+AN14+AI14+AP14+AQ14 -> 0.19285858 | AS14: =R14*S14 -> 1.1666667 | AT14: =(AS14/(AS14+AR14))*100 -> 85.81427
O15: =0.205*2.5/(Lm*Fsw) -> 0.073214286 | Q15: 8 | R15: =VOUT -> 10 | S15: =Q15*$O$12 -> 0.13333333 | T15: =VIN_var -> 4 | U15: =(R15*S15)/(T15*EFF_est) -> 0.33333333 | V15: =IF(S15<((T15^2)*R15)/(2*Fsw*Lm*((T15+R15)^2)),1,2) -> 2 | W15: =CHOOSE(V15,SQRT(2*Lm*R15*S15*Fsw)/T15,R15/(T15+R15)) -> 0.71428571 | X15: =CHOOSE(V15,(Lm*Z15*Fsw)/(R15),1-W15) -> 0.28571429 | Y15: =(T15*W15)/(Lm*Fsw) -> 0.40816327 | Z15: =U15+S15+(Y15) -> 0.87482993 | AA15: =CHOOSE(V15,Z15*SQRT((W15+X15)/3),SQRT((U15^2)+((Y15^2)/12))) -> 0.35354521 | AB15: 0 | AC15: =(AA15^2)*Rdcr -> 0.0012499422 | AD15: =AB15+AC15 -> 0.0012499422 | AE15: =U15*S15*W15 -> 0.031746032 | AF15: =AA15 -> 0.35354521 | AG15: =(AF15^2)*RDS_on -> 0.0008124624 | AH15: =(((R15+T15)*(U15+S15))/2)*Fsw*(tr_sw+tf_sw) -> -0.012675208 | AI15: =AG15+AH15 -> -0.011862746 | AJ15: =S15 -> 0.13333333 | AK15: =CHOOSE(V15,Z15*SQRT(X15/3),SQRT(X15*((Z15^2)+((Y15^2)/3)-(Y15*Z15)))) -> 0.36401977 | AL15: =S15*Vd_rect -> 0.043333333 | AM15: =(R15+T15+Vd_rect)*Qrr*Fsw -> 0 | AN15: =AL15+AM15 -> 0.043333333 | AO15: =(AF15^2)*R_cs -> 0.0012499422 | AP15: =Qg_tot*Vcc*Fsw -> 0.1512 | AQ15: =IQ*T15 -> 0.0132 | AR15: =AO15+AN15+AI15+AP15+AQ15 -> 0.19712053 | AS15: =R15*S15 -> 1.3333333 | AT15: =(AS15/(AS15+AR15))*100 -> 87.120126
Q16: 9 | R16: =VOUT -> 10 | S16: =Q16*$O$12 -> 0.15 | T16: =VIN_var -> 4 | U16: =(R16*S16)/(T16*EFF_est) -> 0.375 | V16: =IF(S16<((T16^2)*R16)/(2*Fsw*Lm*((T16+R16)^2)),1,2) -> 2 | W16: =CHOOSE(V16,SQRT(2*Lm*R16*S16*Fsw)/T16,R16/(T16+R16)) -> 0.71428571 | X16: =CHOOSE(V16,(Lm*Z16*Fsw)/(R16),1-W16) -> 0.28571429 | Y16: =(T16*W16)/(Lm*Fsw) -> 0.40816327 | Z16: =U16+S16+(Y16) -> 0.93316327 | AA16: =CHOOSE(V16,Z16*SQRT((W16+X16)/3),SQRT((U16^2)+((Y16^2)/12))) -> 0.39307519 | AB16: 0 | AC16: =(AA16^2)*Rdcr -> 0.001545081 | AD16: =AB16+AC16 -> 0.001545081 | AE16: =U16*S16*W16 -> 0.040178571 | AF16: =AA16 -> 0.39307519 | AG16: =(AF16^2)*RDS_on -> 0.0010043027 | AH16: =(((R16+T16)*(U16+S16))/2)*Fsw*(tr_sw+tf_sw) -> -0.014259609 | AI16: =AG16+AH16 -> -0.013255307 | AJ16: =S16 -> 0.15 | AK16: =CHOOSE(V16,Z16*SQRT(X16/3),SQRT(X16*((Z16^2)+((Y16^2)/3)-(Y16*Z16)))) -> 0.39476689 | AL16: =S16*Vd_rect -> 0.04875 | AM16: =(R16+T16+Vd_rect)*Qrr*Fsw -> 0 | AN16: =AL16+AM16 -> 0.04875 | AO16: =(AF16^2)*R_cs -> 0.001545081 | AP16: =Qg_tot*Vcc*Fsw -> 0.1512 | AQ16: =IQ*T16 -> 0.0132 | AR16: =AO16+AN16+AI16+AP16+AQ16 -> 0.20143977 | AS16: =R16*S16 -> 1.5 | AT16: =(AS16/(AS16+AR16))*100 -> 88.160629
Q17: 10 | R17: =VOUT -> 10 | S17: =Q17*$O$12 -> 0.16666667 | T17: =VIN_var -> 4 | U17: =(R17*S17)/(T17*EFF_est) -> 0.41666667 | V17: =IF(S17<((T17^2)*R17)/(2*Fsw*Lm*((T17+R17)^2)),1,2) -> 2 | W17: =CHOOSE(V17,SQRT(2*Lm*R17*S17*Fsw)/T17,R17/(T17+R17)) -> 0.71428571 | X17: =CHOOSE(V17,(Lm*Z17*Fsw)/(R17),1-W17) -> 0.28571429 | Y17: =(T17*W17)/(Lm*Fsw) -> 0.40816327 | Z17: =U17+S17+(Y17) -> 0.9914966 | AA17: =CHOOSE(V17,Z17*SQRT((W17+X17)/3),SQRT((U17^2)+((Y17^2)/12))) -> 0.43300602 | AB17: 0 | AC17: =(AA17^2)*Rdcr -> 0.0018749422 | AD17: =AB17+AC17 -> 0.0018749422 | AE17: =U17*S17*W17 -> 0.049603175 | AF17: =AA17 -> 0.43300602 | AG17: =(AF17^2)*RDS_on -> 0.0012187124 | AH17: =(((R17+T17)*(U17+S17))/2)*Fsw*(tr_sw+tf_sw) -> -0.01584401 | AI17: =AG17+AH17 -> -0.014625298 | AJ17: =S17 -> 0.16666667 | AK17: =CHOOSE(V17,Z17*SQRT(X17/3),SQRT(X17*((Z17^2)+((Y17^2)/3)-(Y17*Z17)))) -> 0.42557706 | AL17: =S17*Vd_rect -> 0.054166667 | AM17: =(R17+T17+Vd_rect)*Qrr*Fsw -> 0 | AN17: =AL17+AM17 -> 0.054166667 | AO17: =(AF17^2)*R_cs -> 0.0018749422 | AP17: =Qg_tot*Vcc*Fsw -> 0.1512 | AQ17: =IQ*T17 -> 0.0132 | AR17: =AO17+AN17+AI17+AP17+AQ17 -> 0.20581631 | AS17: =R17*S17 -> 1.6666667 | AT17: =(AS17/(AS17+AR17))*100 -> 89.008375
Q18: 11 | R18: =VOUT -> 10 | S18: =Q18*$O$12 -> 0.18333333 | T18: =VIN_var -> 4 | U18: =(R18*S18)/(T18*EFF_est) -> 0.45833333 | V18: =IF(S18<((T18^2)*R18)/(2*Fsw*Lm*((T18+R18)^2)),1,2) -> 2 | W18: =CHOOSE(V18,SQRT(2*Lm*R18*S18*Fsw)/T18,R18/(T18+R18)) -> 0.71428571 | X18: =CHOOSE(V18,(Lm*Z18*Fsw)/(R18),1-W18) -> 0.28571429 | Y18: =(T18*W18)/(Lm*Fsw) -> 0.40816327 | Z18: =U18+S18+(Y18) -> 1.0498299 | AA18: =CHOOSE(V18,Z18*SQRT((W18+X18)/3),SQRT((U18^2)+((Y18^2)/12))) -> 0.47323625 | AB18: 0 | AC18: =(AA18^2)*Rdcr -> 0.0022395255 | AD18: =AB18+AC18 -> 0.0022395255 | AE18: =U18*S18*W18 -> 0.060019841 | AF18: =AA18 -> 0.47323625 | AG18: =(AF18^2)*RDS_on -> 0.0014556916 | AH18: =(((R18+T18)*(U18+S18))/2)*Fsw*(tr_sw+tf_sw) -> -0.017428411 | AI18: =AG18+AH18 -> -0.01597272 | AJ18: =S18 -> 0.18333333 | AK18: =CHOOSE(V18,Z18*SQRT(X18/3),SQRT(X18*((Z18^2)+((Y18^2)/3)-(Y18*Z18)))) -> 0.45643754 | AL18: =S18*Vd_rect -> 0.059583333 | AM18: =(R18+T18+Vd_rect)*Qrr*Fsw -> 0 | AN18: =AL18+AM18 -> 0.059583333 | AO18: =(AF18^2)*R_cs -> 0.0022395255 | AP18: =Qg_tot*Vcc*Fsw -> 0.1512 | AQ18: =IQ*T18 -> 0.0132 | AR18: =AO18+AN18+AI18+AP18+AQ18 -> 0.21025014 | AS18: =R18*S18 -> 1.8333333 | AT18: =(AS18/(AS18+AR18))*100 -> 89.711693
Q19: 12 | R19: =VOUT -> 10 | S19: =Q19*$O$12 -> 0.2 | T19: =VIN_var -> 4 | U19: =(R19*S19)/(T19*EFF_est) -> 0.5 | V19: =IF(S19<((T19^2)*R19)/(2*Fsw*Lm*((T19+R19)^2)),1,2) -> 2 | W19: =CHOOSE(V19,SQRT(2*Lm*R19*S19*Fsw)/T19,R19/(T19+R19)) -> 0.71428571 | X19: =CHOOSE(V19,(Lm*Z19*Fsw)/(R19),1-W19) -> 0.28571429 | Y19: =(T19*W19)/(Lm*Fsw) -> 0.40816327 | Z19: =U19+S19+(Y19) -> 1.1081633 | AA19: =CHOOSE(V19,Z19*SQRT((W19+X19)/3),SQRT((U19^2)+((Y19^2)/12))) -> 0.51369554 | AB19: 0 | AC19: =(AA19^2)*Rdcr -> 0.002638831 | AD19: =AB19+AC19 -> 0.002638831 | AE19: =U19*S19*W19 -> 0.071428571 | AF19: =AA19 -> 0.51369554 | AG19: =(AF19^2)*RDS_on -> 0.0017152402 | AH19: =(((R19+T19)*(U19+S19))/2)*Fsw*(tr_sw+tf_sw) -> -0.019012812 | AI19: =AG19+AH19 -> -0.017297572 | AJ19: =S19 -> 0.2 | AK19: =CHOOSE(V19,Z19*SQRT(X19/3),SQRT(X19*((Z19^2)+((Y19^2)/3)-(Y19*Z19)))) -> 0.48733875 | AL19: =S19*Vd_rect -> 0.065 | AM19: =(R19+T19+Vd_rect)*Qrr*Fsw -> 0 | AN19: =AL19+AM19 -> 0.065 | AO19: =(AF19^2)*R_cs -> 0.002638831 | AP19: =Qg_tot*Vcc*Fsw -> 0.1512 | AQ19: =IQ*T19 -> 0.0132 | AR19: =AO19+AN19+AI19+AP19+AQ19 -> 0.21474126 | AS19: =R19*S19 -> 2 | AT19: =(AS19/(AS19+AR19))*100 -> 90.304002
Q20: 13 | R20: =VOUT -> 10 | S20: =Q20*$O$12 -> 0.21666667 | T20: =VIN_var -> 4 | U20: =(R20*S20)/(T20*EFF_est) -> 0.54166667 | V20: =IF(S20<((T20^2)*R20)/(2*Fsw*Lm*((T20+R20)^2)),1,2) -> 2 | W20: =CHOOSE(V20,SQRT(2*Lm*R20*S20*Fsw)/T20,R20/(T20+R20)) -> 0.71428571 | X20: =CHOOSE(V20,(Lm*Z20*Fsw)/(R20),1-W20) -> 0.28571429 | Y20: =(T20*W20)/(Lm*Fsw) -> 0.40816327 | Z20: =CHOOSE(V20,Y20,U20+S20+(Y20)) -> 1.1664966 | AA20: =CHOOSE(V20,Z20*SQRT((W20+X20)/3),SQRT((U20^2)+((Y20^2)/12))) -> 0.55433373 | AB20: 0 | AC20: =(AA20^2)*Rdcr -> 0.0030728588 | AD20: =AB20+AC20 -> 0.0030728588 | AE20: =U20*S20*W20 -> 0.083829365 | AF20: =AA20 -> 0.55433373 | AG20: =(AF20^2)*RDS_on -> 0.0019973582 | AH20: =(((R20+T20)*(U20+S20))/2)*Fsw*(tr_sw+tf_sw) -> -0.020597213 | AI20: =AG20+AH20 -> -0.018599855 | AJ20: =S20 -> 0.21666667 | AK20: =CHOOSE(V20,Z20*SQRT(X20/3),SQRT(X20*((Z20^2)+((Y20^2)/3)-(Y20*Z20)))) -> 0.51827342 | AL20: =S20*Vd_rect -> 0.070416667 | AM20: =(R20+T20+Vd_rect)*Qrr*Fsw -> 0 | AN20: =AL20+AM20 -> 0.070416667 | AO20: =(AF20^2)*R_cs -> 0.0030728588 | AP20: =Qg_tot*Vcc*Fsw -> 0.1512 | AQ20: =IQ*T20 -> 0.0132 | AR20: =AO20+AN20+AI20+AP20+AQ20 -> 0.21928967 | AS20: =R20*S20 -> 2.1666667 | AT20: =(AS20/(AS20+AR20))*100 -> 90.80915
Q21: 14 | R21: =VOUT -> 10 | S21: =Q21*$O$12 -> 0.23333333 | T21: =VIN_var -> 4 | U21: =(R21*S21)/(T21*EFF_est) -> 0.58333333 | V21: =IF(S21<((T21^2)*R21)/(2*Fsw*Lm*((T21+R21)^2)),1,2) -> 2 | W21: =CHOOSE(V21,SQRT(2*Lm*R21*S21*Fsw)/T21,R21/(T21+R21)) -> 0.71428571 | X21: =CHOOSE(V21,(Lm*Z21*Fsw)/(R21),1-W21) -> 0.28571429 | Y21: =(T21*W21)/(Lm*Fsw) -> 0.40816327 | Z21: =CHOOSE(V21,Y21,U21+S21+(Y21)) -> 1.2248299 | AA21: =CHOOSE(V21,Z21*SQRT((W21+X21)/3),SQRT((U21^2)+((Y21^2)/12))) -> 0.59511418 | AB21: 0 | AC21: =(AA21^2)*Rdcr -> 0.0035416088 | AD21: =AB21+AC21 -> 0.0035416088 | AE21: =U21*S21*W21 -> 0.097222222 | AF21: =AA21 -> 0.59511418 | AG21: =(AF21^2)*RDS_on -> 0.0023020457 | AH21: =(((R21+T21)*(U21+S21))/2)*Fsw*(tr_sw+tf_sw) -> -0.022181614 | AI21: =AG21+AH21 -> -0.019879569 | AJ21: =S21 -> 0.23333333 | AK21: =CHOOSE(V21,Z21*SQRT(X21/3),SQRT(X21*((Z21^2)+((Y21^2)/3)-(Y21*Z21)))) -> 0.54923588 | AL21: =S21*Vd_rect -> 0.075833333 | AM21: =(R21+T21+Vd_rect)*Qrr*Fsw -> 0 | AN21: =AL21+AM21 -> 0.075833333 | AO21: =(AF21^2)*R_cs -> 0.0035416088 | AP21: =Qg_tot*Vcc*Fsw -> 0.1512 | AQ21: =IQ*T21 -> 0.0132 | AR21: =AO21+AN21+AI21+AP21+AQ21 -> 0.22389537 | AS21: =R21*S21 -> 2.3333333 | AT21: =(AS21/(AS21+AR21))*100 -> 91.244609
Q22: 15 | R22: =VOUT -> 10 | S22: =Q22*$O$12 -> 0.25 | T22: =VIN_var -> 4 | U22: =(R22*S22)/(T22*EFF_est) -> 0.625 | V22: =IF(S22<((T22^2)*R22)/(2*Fsw*Lm*((T22+R22)^2)),1,2) -> 2 | W22: =CHOOSE(V22,SQRT(2*Lm*R22*S22*Fsw)/T22,R22/(T22+R22)) -> 0.71428571 | X22: =CHOOSE(V22,(Lm*Z22*Fsw)/(R22),1-W22) -> 0.28571429 | Y22: =(T22*W22)/(Lm*Fsw) -> 0.40816327 | Z22: =CHOOSE(V22,Y22,U22+S22+(Y22)) -> 1.2831633 | AA22: =CHOOSE(V22,Z22*SQRT((W22+X22)/3),SQRT((U22^2)+((Y22^2)/12))) -> 0.63600952 | AB22: 0 | AC22: =(AA22^2)*Rdcr -> 0.004045081 | AD22: =AB22+AC22 -> 0.004045081 | AE22: =U22*S22*W22 -> 0.11160714 | AF22: =AA22 -> 0.63600952 | AG22: =(AF22^2)*RDS_on -> 0.0026293027 | AH22: =(((R22+T22)*(U22+S22))/2)*Fsw*(tr_sw+tf_sw) -> -0.023766015 | AI22: =AG22+AH22 -> -0.021136713 | AJ22: =S22 -> 0.25 | AK22: =CHOOSE(V22,Z22*SQRT(X22/3),SQRT(X22*((Z22^2)+((Y22^2)/3)-(Y22*Z22)))) -> 0.5802217 | AL22: =S22*Vd_rect -> 0.08125 | AM22: =(R22+T22+Vd_rect)*Qrr*Fsw -> 0 | AN22: =AL22+AM22 -> 0.08125 | AO22: =(AF22^2)*R_cs -> 0.004045081 | AP22: =Qg_tot*Vcc*Fsw -> 0.1512 | AQ22: =IQ*T22 -> 0.0132 | AR22: =AO22+AN22+AI22+AP22+AQ22 -> 0.22855837 | AS22: =R22*S22 -> 2.5 | AT22: =(AS22/(AS22+AR22))*100 -> 91.623475
Q23: 16 | R23: =VOUT -> 10 | S23: =Q23*$O$12 -> 0.26666667 | T23: =VIN_var -> 4 | U23: =(R23*S23)/(T23*EFF_est) -> 0.66666667 | V23: =IF(S23<((T23^2)*R23)/(2*Fsw*Lm*((T23+R23)^2)),1,2) -> 2 | W23: =CHOOSE(V23,SQRT(2*Lm*R23*S23*Fsw)/T23,R23/(T23+R23)) -> 0.71428571 | X23: =CHOOSE(V23,(Lm*Z23*Fsw)/(R23),1-W23) -> 0.28571429 | Y23: =(T23*W23)/(Lm*Fsw) -> 0.40816327 | Z23: =CHOOSE(V23,Y23,U23+S23+(Y23)) -> 1.3414966 | AA23: =CHOOSE(V23,Z23*SQRT((W23+X23)/3),SQRT((U23^2)+((Y23^2)/12))) -> 0.67699893 | AB23: 0 | AC23: =(AA23^2)*Rdcr -> 0.0045832755 | AD23: =AB23+AC23 -> 0.0045832755 | AE23: =U23*S23*W23 -> 0.12698413 | AF23: =AA23 -> 0.67699893 | AG23: =(AF23^2)*RDS_on -> 0.0029791291 | AH23: =(((R23+T23)*(U23+S23))/2)*Fsw*(tr_sw+tf_sw) -> -0.025350416 | AI23: =AG23+AH23 -> -0.022371287 | AJ23: =S23 -> 0.26666667 | AK23: =CHOOSE(V23,Z23*SQRT(X23/3),SQRT(X23*((Z23^2)+((Y23^2)/3)-(Y23*Z23)))) -> 0.61122732 | AL23: =S23*Vd_rect -> 0.086666667 | AM23: =(R23+T23+Vd_rect)*Qrr*Fsw -> 0 | AN23: =AL23+AM23 -> 0.086666667 | AO23: =(AF23^2)*R_cs -> 0.0045832755 | AP23: =Qg_tot*Vcc*Fsw -> 0.1512 | AQ23: =IQ*T23 -> 0.0132 | AR23: =AO23+AN23+AI23+AP23+AQ23 -> 0.23327865 | AS23: =R23*S23 -> 2.6666667 | AT23: =(AS23/(AS23+AR23))*100 -> 91.955757
Q24: 17 | R24: =VOUT -> 10 | S24: =Q24*$O$12 -> 0.28333333 | T24: =VIN_var -> 4 | U24: =(R24*S24)/(T24*EFF_est) -> 0.70833333 | V24: =IF(S24<((T24^2)*R24)/(2*Fsw*Lm*((T24+R24)^2)),1,2) -> 2 | W24: =CHOOSE(V24,SQRT(2*Lm*R24*S24*Fsw)/T24,R24/(T24+R24)) -> 0.71428571 | X24: =CHOOSE(V24,(Lm*Z24*Fsw)/(R24),1-W24) -> 0.28571429 | Y24: =(T24*W24)/(Lm*Fsw) -> 0.40816327 | Z24: =CHOOSE(V24,Y24,U24+S24+(Y24)) -> 1.3998299 | AA24: =CHOOSE(V24,Z24*SQRT((W24+X24)/3),SQRT((U24^2)+((Y24^2)/12))) -> 0.7180663 | AB24: 0 | AC24: =(AA24^2)*Rdcr -> 0.0051561922 | AD24: =AB24+AC24 -> 0.0051561922 | AE24: =U24*S24*W24 -> 0.14335317 | AF24: =AA24 -> 0.7180663 | AG24: =(AF24^2)*RDS_on -> 0.0033515249 | AH24: =(((R24+T24)*(U24+S24))/2)*Fsw*(tr_sw+tf_sw) -> -0.026934817 | AI24: =AG24+AH24 -> -0.023583292 | AJ24: =S24 -> 0.28333333 | AK24: =CHOOSE(V24,Z24*SQRT(X24/3),SQRT(X24*((Z24^2)+((Y24^2)/3)-(Y24*Z24)))) -> 0.64224986 | AL24: =S24*Vd_rect -> 0.092083333 | AM24: =(R24+T24+Vd_rect)*Qrr*Fsw -> 0 | AN24: =AL24+AM24 -> 0.092083333 | AO24: =(AF24^2)*R_cs -> 0.0051561922 | AP24: =Qg_tot*Vcc*Fsw -> 0.1512 | AQ24: =IQ*T24 -> 0.0132 | AR24: =AO24+AN24+AI24+AP24+AQ24 -> 0.23805623 | AS24: =R24*S24 -> 2.8333333 | AT24: =(AS24/(AS24+AR24))*100 -> 92.249234
Q25: 18 | R25: =VOUT -> 10 | S25: =Q25*$O$12 -> 0.3 | T25: =VIN_var -> 4 | U25: =(R25*S25)/(T25*EFF_est) -> 0.75 | V25: =IF(S25<((T25^2)*R25)/(2*Fsw*Lm*((T25+R25)^2)),1,2) -> 2 | W25: =CHOOSE(V25,SQRT(2*Lm*R25*S25*Fsw)/T25,R25/(T25+R25)) -> 0.71428571 | X25: =CHOOSE(V25,(Lm*Z25*Fsw)/(R25),1-W25) -> 0.28571429 | Y25: =(T25*W25)/(Lm*Fsw) -> 0.40816327 | Z25: =CHOOSE(V25,Y25,U25+S25+(Y25)) -> 1.4581633 | AA25: =CHOOSE(V25,Z25*SQRT((W25+X25)/3),SQRT((U25^2)+((Y25^2)/12))) -> 0.75919899 | AB25: 0 | AC25: =(AA25^2)*Rdcr -> 0.005763831 | AD25: =AB25+AC25 -> 0.005763831 | AE25: =U25*S25*W25 -> 0.16071429 | AF25: =AA25 -> 0.75919899 | AG25: =(AF25^2)*RDS_on -> 0.0037464902 | AH25: =(((R25+T25)*(U25+S25))/2)*Fsw*(tr_sw+tf_sw) -> -0.028519218 | AI25: =AG25+AH25 -> -0.024772728 | AJ25: =S25 -> 0.3 | AK25: =CHOOSE(V25,Z25*SQRT(X25/3),SQRT(X25*((Z25^2)+((Y25^2)/3)-(Y25*Z25)))) -> 0.673287 | AL25: =S25*Vd_rect -> 0.0975 | AM25: =(R25+T25+Vd_rect)*Qrr*Fsw -> 0 | AN25: =AL25+AM25 -> 0.0975 | AO25: =(AF25^2)*R_cs -> 0.005763831 | AP25: =Qg_tot*Vcc*Fsw -> 0.1512 | AQ25: =IQ*T25 -> 0.0132 | AR25: =AO25+AN25+AI25+AP25+AQ25 -> 0.2428911 | AS25: =R25*S25 -> 3 | AT25: =(AS25/(AS25+AR25))*100 -> 92.510044
Q26: 19 | R26: =VOUT -> 10 | S26: =Q26*$O$12 -> 0.31666667 | T26: =VIN_var -> 4 | U26: =(R26*S26)/(T26*EFF_est) -> 0.79166667 | V26: =IF(S26<((T26^2)*R26)/(2*Fsw*Lm*((T26+R26)^2)),1,2) -> 2 | W26: =CHOOSE(V26,SQRT(2*Lm*R26*S26*Fsw)/T26,R26/(T26+R26)) -> 0.71428571 | X26: =CHOOSE(V26,(Lm*Z26*Fsw)/(R26),1-W26) -> 0.28571429 | Y26: =(T26*W26)/(Lm*Fsw) -> 0.40816327 | Z26: =CHOOSE(V26,Y26,U26+S26+(Y26)) -> 1.5164966 | AA26: =CHOOSE(V26,Z26*SQRT((W26+X26)/3),SQRT((U26^2)+((Y26^2)/12))) -> 0.80038692 | AB26: 0 | AC26: =(AA26^2)*Rdcr -> 0.0064061922 | AD26: =AB26+AC26 -> 0.0064061922 | AE26: =U26*S26*W26 -> 0.17906746 | AF26: =AA26 -> 0.80038692 | AG26: =(AF26^2)*RDS_on -> 0.0041640249 | AH26: =(((R26+T26)*(U26+S26))/2)*Fsw*(tr_sw+tf_sw) -> -0.030103619 | AI26: =AG26+AH26 -> -0.025939595 | AJ26: =S26 -> 0.31666667 | AK26: =CHOOSE(V26,Z26*SQRT(X26/3),SQRT(X26*((Z26^2)+((Y26^2)/3)-(Y26*Z26)))) -> 0.7043368 | AL26: =S26*Vd_rect -> 0.10291667 | AM26: =(R26+T26+Vd_rect)*Qrr*Fsw -> 0 | AN26: =AL26+AM26 -> 0.10291667 | AO26: =(AF26^2)*R_cs -> 0.0064061922 | AP26: =Qg_tot*Vcc*Fsw -> 0.1512 | AQ26: =IQ*T26 -> 0.0132 | AR26: =AO26+AN26+AI26+AP26+AQ26 -> 0.24778326 | AS26: =R26*S26 -> 3.1666667 | AT26: =(AS26/(AS26+AR26))*100 -> 92.743099
Q27: 20 | R27: =VOUT -> 10 | S27: =Q27*$O$12 -> 0.33333333 | T27: =VIN_var -> 4 | U27: =(R27*S27)/(T27*EFF_est) -> 0.83333333 | V27: =IF(S27<((T27^2)*R27)/(2*Fsw*Lm*((T27+R27)^2)),1,2) -> 2 | W27: =CHOOSE(V27,SQRT(2*Lm*R27*S27*Fsw)/T27,R27/(T27+R27)) -> 0.71428571 | X27: =CHOOSE(V27,(Lm*Z27*Fsw)/(R27),1-W27) -> 0.28571429 | Y27: =(T27*W27)/(Lm*Fsw) -> 0.40816327 | Z27: =CHOOSE(V27,Y27,U27+S27+(Y27)) -> 1.5748299 | AA27: =CHOOSE(V27,Z27*SQRT((W27+X27)/3),SQRT((U27^2)+((Y27^2)/12))) -> 0.84162197 | AB27: 0 | AC27: =(AA27^2)*Rdcr -> 0.0070832755 | AD27: =AB27+AC27 -> 0.0070832755 | AE27: =U27*S27*W27 -> 0.1984127 | AF27: =AA27 -> 0.84162197 | AG27: =(AF27^2)*RDS_on -> 0.0046041291 | AH27: =(((R27+T27)*(U27+S27))/2)*Fsw*(tr_sw+tf_sw) -> -0.03168802 | AI27: =AG27+AH27 -> -0.027083891 | AJ27: =S27 -> 0.33333333 | AK27: =CHOOSE(V27,Z27*SQRT(X27/3),SQRT(X27*((Z27^2)+((Y27^2)/3)-(Y27*Z27)))) -> 0.73539766 | AL27: =S27*Vd_rect -> 0.10833333 | AM27: =(R27+T27+Vd_rect)*Qrr*Fsw -> 0 | AN27: =AL27+AM27 -> 0.10833333 | AO27: =(AF27^2)*R_cs -> 0.0070832755 | AP27: =Qg_tot*Vcc*Fsw -> 0.1512 | AQ27: =IQ*T27 -> 0.0132 | AR27: =AO27+AN27+AI27+AP27+AQ27 -> 0.25273272 | AS27: =R27*S27 -> 3.3333333 | AT27: =(AS27/(AS27+AR27))*100 -> 92.952369
Q28: 21 | R28: =VOUT -> 10 | S28: =Q28*$O$12 -> 0.35 | T28: =VIN_var -> 4 | U28: =(R28*S28)/(T28*EFF_est) -> 0.875 | V28: =IF(S28<((T28^2)*R28)/(2*Fsw*Lm*((T28+R28)^2)),1,2) -> 2 | W28: =CHOOSE(V28,SQRT(2*Lm*R28*S28*Fsw)/T28,R28/(T28+R28)) -> 0.71428571 | X28: =CHOOSE(V28,(Lm*Z28*Fsw)/(R28),1-W28) -> 0.28571429 | Y28: =(T28*W28)/(Lm*Fsw) -> 0.40816327 | Z28: =CHOOSE(V28,Y28,U28+S28+(Y28)) -> 1.6331633 | AA28: =CHOOSE(V28,Z28*SQRT((W28+X28)/3),SQRT((U28^2)+((Y28^2)/12))) -> 0.88289756 | AB28: 0 | AC28: =(AA28^2)*Rdcr -> 0.007795081 | AD28: =AB28+AC28 -> 0.007795081 | AE28: =U28*S28*W28 -> 0.21875 | AF28: =AA28 -> 0.88289756 | AG28: =(AF28^2)*RDS_on -> 0.0050668027 | AH28: =(((R28+T28)*(U28+S28))/2)*Fsw*(tr_sw+tf_sw) -> -0.033272421 | AI28: =AG28+AH28 -> -0.028205619 | AJ28: =S28 -> 0.35 | AK28: =CHOOSE(V28,Z28*SQRT(X28/3),SQRT(X28*((Z28^2)+((Y28^2)/3)-(Y28*Z28)))) -> 0.76646823 | AL28: =S28*Vd_rect -> 0.11375 | AM28: =(R28+T28+Vd_rect)*Qrr*Fsw -> 0 | AN28: =AL28+AM28 -> 0.11375 | AO28: =(AF28^2)*R_cs -> 0.007795081 | AP28: =Qg_tot*Vcc*Fsw -> 0.1512 | AQ28: =IQ*T28 -> 0.0132 | AR28: =AO28+AN28+AI28+AP28+AQ28 -> 0.25773946 | AS28: =R28*S28 -> 3.5 | AT28: =(AS28/(AS28+AR28))*100 -> 93.141103
Q29: 22 | R29: =VOUT -> 10 | S29: =Q29*$O$12 -> 0.36666667 | T29: =VIN_var -> 4 | U29: =(R29*S29)/(T29*EFF_est) -> 0.91666667 | V29: =IF(S29<((T29^2)*R29)/(2*Fsw*Lm*((T29+R29)^2)),1,2) -> 2 | W29: =CHOOSE(V29,SQRT(2*Lm*R29*S29*Fsw)/T29,R29/(T29+R29)) -> 0.71428571 | X29: =CHOOSE(V29,(Lm*Z29*Fsw)/(R29),1-W29) -> 0.28571429 | Y29: =(T29*W29)/(Lm*Fsw) -> 0.40816327 | Z29: =CHOOSE(V29,Y29,U29+S29+(Y29)) -> 1.6914966 | AA29: =CHOOSE(V29,Z29*SQRT((W29+X29)/3),SQRT((U29^2)+((Y29^2)/12))) -> 0.92420825 | AB29: 0 | AC29: =(AA29^2)*Rdcr -> 0.0085416088 | AD29: =AB29+AC29 -> 0.0085416088 | AE29: =U29*S29*W29 -> 0.24007937 | AF29: =AA29 -> 0.92420825 | AG29: =(AF29^2)*RDS_on -> 0.0055520457 | AH29: =(((R29+T29)*(U29+S29))/2)*Fsw*(tr_sw+tf_sw) -> -0.034856823 | AI29: =AG29+AH29 -> -0.029304777 | AJ29: =S29 -> 0.36666667 | AK29: =CHOOSE(V29,Z29*SQRT(X29/3),SQRT(X29*((Z29^2)+((Y29^2)/3)-(Y29*Z29)))) -> 0.79754738 | AL29: =S29*Vd_rect -> 0.11916667 | AM29: =(R29+T29+Vd_rect)*Qrr*Fsw -> 0 | AN29: =AL29+AM29 -> 0.11916667 | AO29: =(AF29^2)*R_cs -> 0.0085416088 | AP29: =Qg_tot*Vcc*Fsw -> 0.1512 | AQ29: =IQ*T29 -> 0.0132 | AR29: =AO29+AN29+AI29+AP29+AQ29 -> 0.2628035 | AS29: =R29*S29 -> 3.6666667 | AT29: =(AS29/(AS29+AR29))*100 -> 93.311986
Q30: 23 | R30: =VOUT -> 10 | S30: =Q30*$O$12 -> 0.38333333 | T30: =VIN_var -> 4 | U30: =(R30*S30)/(T30*EFF_est) -> 0.95833333 | V30: =IF(S30<((T30^2)*R30)/(2*Fsw*Lm*((T30+R30)^2)),1,2) -> 2 | W30: =CHOOSE(V30,SQRT(2*Lm*R30*S30*Fsw)/T30,R30/(T30+R30)) -> 0.71428571 | X30: =CHOOSE(V30,(Lm*Z30*Fsw)/(R30),1-W30) -> 0.28571429 | Y30: =(T30*W30)/(Lm*Fsw) -> 0.40816327 | Z30: =CHOOSE(V30,Y30,U30+S30+(Y30)) -> 1.7498299 | AA30: =CHOOSE(V30,Z30*SQRT((W30+X30)/3),SQRT((U30^2)+((Y30^2)/12))) -> 0.96554952 | AB30: 0 | AC30: =(AA30^2)*Rdcr -> 0.0093228588 | AD30: =AB30+AC30 -> 0.0093228588 | AE30: =U30*S30*W30 -> 0.26240079 | AF30: =AA30 -> 0.96554952 | AG30: =(AF30^2)*RDS_on -> 0.0060598582 | AH30: =(((R30+T30)*(U30+S30))/2)*Fsw*(tr_sw+tf_sw) -> -0.036441224 | AI30: =AG30+AH30 -> -0.030381365 | AJ30: =S30 -> 0.38333333 | AK30: =CHOOSE(V30,Z30*SQRT(X30/3),SQRT(X30*((Z30^2)+((Y30^2)/3)-(Y30*Z30)))) -> 0.82863414 | AL30: =S30*Vd_rect -> 0.12458333 | AM30: =(R30+T30+Vd_rect)*Qrr*Fsw -> 0 | AN30: =AL30+AM30 -> 0.12458333 | AO30: =(AF30^2)*R_cs -> 0.0093228588 | AP30: =Qg_tot*Vcc*Fsw -> 0.1512 | AQ30: =IQ*T30 -> 0.0132 | AR30: =AO30+AN30+AI30+AP30+AQ30 -> 0.26792483 | AS30: =R30*S30 -> 3.8333333 | AT30: =(AS30/(AS30+AR30))*100 -> 93.467253
Q31: 24 | R31: =VOUT -> 10 | S31: =Q31*$O$12 -> 0.4 | T31: =VIN_var -> 4 | U31: =(R31*S31)/(T31*EFF_est) -> 1 | V31: =IF(S31<((T31^2)*R31)/(2*Fsw*Lm*((T31+R31)^2)),1,2) -> 2 | W31: =CHOOSE(V31,SQRT(2*Lm*R31*S31*Fsw)/T31,R31/(T31+R31)) -> 0.71428571 | X31: =CHOOSE(V31,(Lm*Z31*Fsw)/(R31),1-W31) -> 0.28571429 | Y31: =(T31*W31)/(Lm*Fsw) -> 0.40816327 | Z31: =CHOOSE(V31,Y31,U31+S31+(Y31)) -> 1.8081633 | AA31: =CHOOSE(V31,Z31*SQRT((W31+X31)/3),SQRT((U31^2)+((Y31^2)/12))) -> 1.0069176 | AB31: 0 | AC31: =(AA31^2)*Rdcr -> 0.010138831 | AD31: =AB31+AC31 -> 0.010138831 | AE31: =U31*S31*W31 -> 0.28571429 | AF31: =AA31 -> 1.0069176 | AG31: =(AF31^2)*RDS_on -> 0.0065902402 | AH31: =(((R31+T31)*(U31+S31))/2)*Fsw*(tr_sw+tf_sw) -> -0.038025625 | AI31: =AG31+AH31 -> -0.031435384 | AJ31: =S31 -> 0.4 | AK31: =CHOOSE(V31,Z31*SQRT(X31/3),SQRT(X31*((Z31^2)+((Y31^2)/3)-(Y31*Z31)))) -> 0.8597277 | AL31: =S31*Vd_rect -> 0.13 | AM31: =(R31+T31+Vd_rect)*Qrr*Fsw -> 0 | AN31: =AL31+AM31 -> 0.13 | AO31: =(AF31^2)*R_cs -> 0.010138831 | AP31: =Qg_tot*Vcc*Fsw -> 0.1512 | AQ31: =IQ*T31 -> 0.0132 | AR31: =AO31+AN31+AI31+AP31+AQ31 -> 0.27310345 | AS31: =R31*S31 -> 4 | AT31: =(AS31/(AS31+AR31))*100 -> 93.60878
... Q157: 150 | R157: =VOUT -> 10 | S157: =Q157*$O$12 -> 2.5 | T157: =VIN_var -> 4 | U157: =(R157*S157)/(T157*EFF_est) -> 6.25 | V157: =IF(S157<((T157^2)*R157)/(2*Fsw*Lm*((T157+R157)^2)),1,2) -> 2 | W157: =CHOOSE(V157,SQRT(2*Lm*R157*S157*Fsw)/T157,R157/(T157+R157)) -> 0.71428571 | X157: =CHOOSE(V157,(Lm*Z157*Fsw)/(R157),1-W157) -> 0.28571429 | Y157: =(T157*W157)/(Lm*Fsw) -> 0.40816327 | Z157: =CHOOSE(V157,Y157,U157+S157+(Y157)) -> 9.1581633 | AA157: =CHOOSE(V157,Z157*SQRT((W157+X157)/3),SQRT((U157^2)+((Y157^2)/12))) -> 6.2511105 | AB157: 0 | AC157: =(AA157^2)*Rdcr -> 0.39076383 | AD157: =AB157+AC157 -> 0.39076383 | AE157: =U157*S157*W157 -> 11.160714 | AF157: =AA157 -> 6.2511105 | AG157: =(AF157^2)*RDS_on -> 0.25399649 | AH157: =(((R157+T157)*(U157+S157))/2)*Fsw*(tr_sw+tf_sw) -> -0.23766015 | AI157: =AG157+AH157 -> 0.016336337 | AJ157: =S157 -> 2.5 | AK157: =CHOOSE(V157,Z157*SQRT(X157/3),SQRT(X157*((Z157^2)+((Y157^2)/3)-(Y157*Z157)))) -> 4.7865723 | AL157: =S157*Vd_rect -> 0.8125 | AM157: =(R157+T157+Vd_rect)*Qrr*Fsw -> 0 | AN157: =AL157+AM157 -> 0.8125 | AO157: =(AF157^2)*R_cs -> 0.39076383 | AP157: =Qg_tot*Vcc*Fsw -> 0.1512 | AQ157: =IQ*T157 -> 0.0132 | AR157: =AO157+AN157+AI157+AP157+AQ157 -> 1.3840002 | AS157: =R157*S157 -> 25 | AT157: =(AS157/(AS157+AR157))*100 -> 94.754396

Sheet Loop_Modeling
A1: EXCEL Variables Names/Calculations | N1: Calculations
B2: Input from user = | AF2: Needs to be updated for DCM operation
B3: Output = | O3: Operating mode
B4: Constant | P4: Plant Transfer Function | AS4: Error Amplifier | BF4: CCM Open Loop Response | BI4: DCM Open Loop Response | BL4: Displayed Loop Calclation
Q5: wp_lf | T5: wz_esr | W5: wz_esr | Z5: Sampling | AC5: Total | AG5: wp_lf | AJ5: wz_esr | AM5: wz_RHP | AP5: Total | AT5: wp0_ea | AW5: wp1_ea | AZ5: wz_ea | BC5: Total | BF5: Total | BI5: Total | BL5: Total
A6: Variable Name | B6: Value | C6: STD Units | E6: Notes | P6: ADC | Q6: Complex | R6: Gain | S6: Phase | T6: Complex | U6: Gain | V6: Phase | W6: Complex | X6: Gain | Y6: Phase | Z6: Complex | AA6: Gain | AB6: Phase | AC6: COMPLEX | AD6: Gain | AE6: Phase | AF6: ADC | AG6: Complex | AH6: Gain | AI6: Phase | AJ6: Complex | AK6: Gain | AL6: Phase | AM6: Complex | AN6: Gain | AO6: Phase | AP6: COMPLEX | AQ6: Gain | AR6: Phase | AS6: ADC_ea | AT6: Complex | AU6: Gain | AV6: Phase | AW6: Complex | AX6: Gain | AY6: Phase | AZ6: Complex | BA6: Gain | BB6: Phase | BC6: COMPLEX | BD6: Gain | BE6: Phase | BF6: COMPLEX | BG6: Gain | BH6: Phase | BI6: COMPLEX | BJ6: Gain | BK6: Phase | BL6: Gain | BM6: Phase
N7: Frcoss (VIN)min | O7: =fcross -> 700 | P7: =COMPLEX(ADC_VINmin,0) -> 46,9565217391304 | Q7: =IMSUM(COMPLEX(1,0),IMDIV(COMPLEX(0,2*PI()*O7),COMPLEX(wp_lf_VINmin,0))) -> 1+5,56854127398038i | R7: =IMABS(Q7) -> 5.6576189 | S7: =IMARGUMENT(Q7) -> 1.39311 | T7: =IMSUM(COMPLEX(1,0),IMDIV(COMPLEX(0,2*PI()*O7),COMPLEX(wz_esr_VINmin,0))) -> 1+0,0689642419316032i | U7: =IMABS(T7) -> 1.0023752 | V7: =IMARGUMENT(T7) -> 0.06885522 | W7: =IMSUB(COMPLEX(1,0),IMDIV(COMPLEX(0,2*PI()*O7),COMPLEX(wz_RHP_VINmin,0))) -> 1-0,158824961931484i | X7: =IMABS(W7) -> 1.0125341 | Y7: =IMARGUMENT(W7) -> -0.15750934 | Z7: =IMSUM(COMPLEX(1,0),IMDIV(COMPLEX(0,2*PI()*O7),COMPLEX(Q_VINmin*(wsl_VINmin/2),0)),IMDIV(IMPOWER(COMPLEX(0,2*PI()*O7),2),IMPOWER(COMPLEX(wsl_VINmin/2,0),2))) -> 0,999996+0,0274043543782371i | AA7: =IMABS(Z7) -> 1.0003714 | AB7: =IMARGUMENT(Z7) -> 0.027397607 | AC7: =(IMDIV(IMPRODUCT(P7,T7,W7),IMPRODUCT(Q7,Z7))) -> 0,518669220271543-8,40457024143729i | AD7: =20*LOG(IMABS(AC7)) -> 18.506819 | AE7: =(180/PI())*IMARGUMENT(AC7) -> -86.468598 | AF7: =COMPLEX($B$68,0) -> 326,048966736478 | AG7: =IMSUM(COMPLEX(1,0),IMDIV(COMPLEX(0,2*PI()*O7),COMPLEX(wp_lf_DCM,0))) -> 1+3,6945129606216i | AH7: =IMABS(AG7) -> 3.8274569 | AI7: =IMARGUMENT(AG7) -> 1.3064586 | AJ7: =IMSUM(COMPLEX(1,0),IMDIV(COMPLEX(0,2*PI()*O7),COMPLEX(wz1_dcm,0))) -> 1+0,0689642419316032i | AK7: =IMABS(AJ7) -> 1.0023752 | AL7: =IMARGUMENT(AJ7) -> 0.06885522 | AM7: =IMSUB(COMPLEX(1,0),IMDIV(COMPLEX(0,2*PI()*O7),COMPLEX(wz2_dcm,0))) -> 1-0,0113815006815577i | AN7: =IMABS(AM7) -> 1.0000648 | AO7: =IMARGUMENT(AM7) -> -0.011381009 | AP7: =(IMDIV(IMPRODUCT(AF7,AJ7,AM7),IMPRODUCT(AG7))) -> 27,0091541241351-81,0108766806122i | AQ7: =20*LOG(IMABS(AP7)) -> 38.628619 | AR7: =(180/PI())*IMARGUMENT(AP7) -> -71.561532 | AS7: =COMPLEX(Adc_ea,0) -> -0,000100699300699301 | AT7: =COMPLEX(0,2*PI()*O7*wp0_ea) -> 0,000988282216966277i | AU7: =IMABS(AT7) -> 0.00098828222 | AV7: =IMARGUMENT(AT7) -> 1.5707963 | AW7: =IMSUM(COMPLEX(1,0),IMDIV(COMPLEX(0,2*PI()*O7),COMPLEX(wp1_ea,0))) -> 1+0,0505982368194992i | AX7: =IMABS(AW7) -> 1.0012793 | AY7: =IMARGUMENT(AW7) -> 0.050555123 | AZ7: =IMSUM(COMPLEX(1,0),IMDIV(COMPLEX(0,2*PI()*O7),COMPLEX(wz_ea,0))) -> 1+2,41902634326414i | BA7: =IMABS(AZ7) -> 2.617573 | BB7: =IMARGUMENT(AZ7) -> 1.1788009 | BC7: =IMPRODUCT(AS7,IMDIV(AZ7,IMPRODUCT(AT7,AW7))) -> -0,240710607118291+0,114072796161721i | BD7: =20*LOG(IMABS(BC7)) -> -11.490219 | BE7: =(180/PI())*IMARGUMENT(BC7) -> 154.64372 | BF7: =IMPRODUCT(AC7,BC7) -> 0,833883645073208+2,08223525362409i | BG7: =20*LOG(IMABS(BF7)) -> 7.0165998 | BH7: =(180/PI())*IMARGUMENT(BF7) -> 68.175121 | BI7: =IMPRODUCT(AP7,BC7) -> 2,73974733549774+22,5811870418781i | BJ7: =20*LOG(IMABS(BI7)) -> 27.1384 | BK7: =(180/PI())*IMARGUMENT(BI7) -> 83.082187 | BL7: =IF($B$31=0,BJ7,BG7) -> 7.0165998 | BM7: =IF($B$31=0,BK7,BH7) -> 68.175121
N8: Fcross | O8: =fcross -> 700 | P8: =COMPLEX(Adc,0) -> 60 | Q8: =IMSUM(COMPLEX(1,0),IMDIV(COMPLEX(0,2*PI()*O8),COMPLEX(wp_lf,0))) -> 1+5,74702016096692i | R8: =IMABS(Q8) -> 5.833373 | S8: =IMARGUMENT(Q8) -> 1.398518 | T8: =IMSUM(COMPLEX(1,0),IMDIV(COMPLEX(0,2*PI()*O8),COMPLEX(wz_esr,0))) -> 1+0,0689642419316032i | U8: =IMABS(T8) -> 1.0023752 | V8: =IMARGUMENT(T8) -> 0.06885522 | W8: =IMSUB(COMPLEX(1,0),IMDIV(COMPLEX(0,2*PI()*O8),COMPLEX(wz_rhp,0))) -> 1-0,0962112750161874i | X8: =IMABS(W8) -> 1.0046176 | Y8: =IMARGUMENT(W8) -> -0.09591605 | Z8: =IMSUM(COMPLEX(1,0),IMDIV(COMPLEX(0,2*PI()*O8),COMPLEX(Q*(wsl/2),0)),IMDIV(IMPOWER(COMPLEX(0,2*PI()*O8),2),IMPOWER(COMPLEX(wsl/2,0),2))) -> 0,999996+0,0256712999693338i | AA8: =IMABS(Z8) -> 1.0003255 | AB8: =IMARGUMENT(Z8) -> 0.025665766 | AC8: =(IMDIV(IMPRODUCT(P8,T8,W8),IMPRODUCT(Q8,Z8))) -> 1,23492958007548-10,2804062547733i | AD8: =20*LOG(IMABS(AC8)) -> 20.302426 | AE8: =(180/PI())*IMARGUMENT(AC8) -> -83.15019 | AF8: =COMPLEX($B$68,0) -> 326,048966736478 | AG8: =IMSUM(COMPLEX(1,0),IMDIV(COMPLEX(0,2*PI()*O8),COMPLEX(wp_lf_DCM,0))) -> 1+3,6945129606216i | AH8: =IMABS(AG8) -> 3.8274569 | AI8: =IMARGUMENT(AG8) -> 1.3064586 | AJ8: =IMSUM(COMPLEX(1,0),IMDIV(COMPLEX(0,2*PI()*O8),COMPLEX(wz1_dcm,0))) -> 1+0,0689642419316032i | AK8: =IMABS(AJ8) -> 1.0023752 | AL8: =IMARGUMENT(AJ8) -> 0.06885522 | AM8: =IMSUB(COMPLEX(1,0),IMDIV(COMPLEX(0,2*PI()*O8),COMPLEX(wz2_dcm,0))) -> 1-0,0113815006815577i | AN8: =IMABS(AM8) -> 1.0000648 | AO8: =IMARGUMENT(AM8) -> -0.011381009 | AP8: =(IMDIV(IMPRODUCT(AF8,AJ8,AM8),IMPRODUCT(AG8))) -> 27,0091541241351-81,0108766806122i | AQ8: =20*LOG(IMABS(AP8)) -> 38.628619 | AR8: =(180/PI())*IMARGUMENT(AP8) -> -71.561532 | AS8: =COMPLEX(Adc_ea,0) -> -0,000100699300699301 | AT8: =COMPLEX(0,2*PI()*O8*wp0_ea) -> 0,000988282216966277i | AU8: =IMABS(AT8) -> 0.00098828222 | AV8: =IMARGUMENT(AT8) -> 1.5707963 | AW8: =IMSUM(COMPLEX(1,0),IMDIV(COMPLEX(0,2*PI()*O8),COMPLEX(wp1_ea,0))) -> 1+0,0505982368194992i | AX8: =IMABS(AW8) -> 1.0012793 | AY8: =IMARGUMENT(AW8) -> 0.050555123 | AZ8: =IMSUM(COMPLEX(1,0),IMDIV(COMPLEX(0,2*PI()*O8),COMPLEX(wz_ea,0))) -> 1+2,41902634326414i | BA8: =IMABS(AZ8) -> 2.617573 | BB8: =IMARGUMENT(AZ8) -> 1.1788009 | BC8: =IMPRODUCT(AS8,IMDIV(AZ8,IMPRODUCT(AT8,AW8))) -> -0,240710607118291+0,114072796161721i | BD8: =20*LOG(IMABS(BC8)) -> -11.490219 | BE8: =(180/PI())*IMARGUMENT(BC8) -> 154.64372 | BF8: =IMPRODUCT(AC8,BC8) -> 0,875454038192131+2,61547470127119i | BG8: =20*LOG(IMABS(BF8)) -> 8.8122071 | BH8: =(180/PI())*IMARGUMENT(BF8) -> 71.49353 | BI8: =IMPRODUCT(AP8,BC8) -> 2,73974733549774+22,5811870418781i | BJ8: =20*LOG(IMABS(BI8)) -> 27.1384 | BK8: =(180/PI())*IMARGUMENT(BI8) -> 83.082187 | BL8: =IF($B$31=0,BJ8,BG8) -> 8.8122071 | BM8: =IF($B$31=0,BK8,BH8) -> 71.49353
A9: Input Parameters | N9: wz_RHP | O9: =IF($B$31=0,B74,wz_rhp/(2*PI())) -> 7275.6545 | P9: =COMPLEX(Adc,0) -> 60 | Q9: =IMSUM(COMPLEX(1,0),IMDIV(COMPLEX(0,2*PI()*O9),COMPLEX(wp_lf,0))) -> 1+59,7333333333333i | R9: =IMABS(Q9) -> 59.741703 | S9: =IMARGUMENT(Q9) -> 1.5540568 | T9: =IMSUM(COMPLEX(1,0),IMDIV(COMPLEX(0,2*PI()*O9),COMPLEX(wz_esr,0))) -> 1+0,7168i | U9: =IMABS(T9) -> 1.2303667 | V9: =IMARGUMENT(T9) -> 0.62191237 | W9: =IMSUB(COMPLEX(1,0),IMDIV(COMPLEX(0,2*PI()*O9),COMPLEX(wz_rhp,0))) -> 1-i | X9: =IMABS(W9) -> 1.4142136 | Y9: =IMARGUMENT(W9) -> -0.78539816 | Z9: =IMSUM(COMPLEX(1,0),IMDIV(COMPLEX(0,2*PI()*O9),COMPLEX(Q*(wsl/2),0)),IMDIV(IMPOWER(COMPLEX(0,2*PI()*O9),2),IMPOWER(COMPLEX(wsl/2,0),2))) -> 0,999567876334653+0,266822157434403i | AA9: =IMABS(Z9) -> 1.0345675 | AB9: =IMARGUMENT(Z9) -> 0.26085523 | AC9: =(IMDIV(IMPRODUCT(P9,T9,W9),IMPRODUCT(Q9,Z9))) -> -0,66958746144967-1,55075136470749i | AD9: =20*LOG(IMABS(AC9)) -> 4.5532874 | AE9: =(180/PI())*IMARGUMENT(AC9) -> -113.35385 | AF9: =COMPLEX($B$68,0) -> 326,048966736478 | AG9: =IMSUM(COMPLEX(1,0),IMDIV(COMPLEX(0,2*PI()*O9),COMPLEX(wp_lf_DCM,0))) -> 1+38,4i | AH9: =IMABS(AG9) -> 38.413019 | AI9: =IMARGUMENT(AG9) -> 1.5447605 | AJ9: =IMSUM(COMPLEX(1,0),IMDIV(COMPLEX(0,2*PI()*O9),COMPLEX(wz1_dcm,0))) -> 1+0,7168i | AK9: =IMABS(AJ9) -> 1.2303667 | AL9: =IMARGUMENT(AJ9) -> 0.62191237 | AM9: =IMSUB(COMPLEX(1,0),IMDIV(COMPLEX(0,2*PI()*O9),COMPLEX(wz2_dcm,0))) -> 1-0,118296953030118i | AN9: =IMABS(AM9) -> 1.0069728 | AO9: =IMARGUMENT(AM9) -> -0.11774972 | AP9: =(IMDIV(IMPRODUCT(AF9,AJ9,AM9),IMPRODUCT(AG9))) -> 5,31806384990021-9,07235178300411i | AQ9: =20*LOG(IMABS(AP9)) -> 20.437134 | AR9: =(180/PI())*IMARGUMENT(AP9) -> -59.621867 | AS9: =COMPLEX(Adc_ea,0) -> -0,000100699300699301 | AT9: =COMPLEX(0,2*PI()*O9*wp0_ea) -> 0,010272i | AU9: =IMABS(AT9) -> 0.010272 | AV9: =IMARGUMENT(AT9) -> 1.5707963 | AW9: =IMSUM(COMPLEX(1,0),IMDIV(COMPLEX(0,2*PI()*O9),COMPLEX(wp1_ea,0))) -> 1+0,525907559285396i | AX9: =IMABS(AW9) -> 1.1298578 | AY9: =IMARGUMENT(AW9) -> 0.4841582 | AZ9: =IMSUM(COMPLEX(1,0),IMDIV(COMPLEX(0,2*PI()*O9),COMPLEX(wz_ea,0))) -> 1+25,1428571428571i | BA9: =IMABS(AZ9) -> 25.162736 | BB9: =IMARGUMENT(AZ9) -> 1.5310446 | BC9: =IMPRODUCT(AS9,IMDIV(AZ9,IMPRODUCT(AT9,AW9))) -> -0,189041896487031+0,109221843215495i | BD9: =20*LOG(IMABS(BC9)) -> -13.21789 | BE9: =(180/PI())*IMARGUMENT(BC9) -> 149.98217 | BF9: =IMPRODUCT(AC9,BC9) -> 0,295956005998679+0,220023402230638i | BG9: =20*LOG(IMABS(BF9)) -> -8.6646028 | BH9: =(180/PI())*IMARGUMENT(BF9) -> 36.628323 | BI9: =IMPRODUCT(AP9,BC9) -> -0,0144378917851656+2,29590332268039i | BJ9: =20*LOG(IMABS(BI9)) -> 7.2192437 | BK9: =(180/PI())*IMARGUMENT(BI9) -> 90.360302 | BL9: =IF($B$31=0,BJ9,BG9) -> -8.6646028 | BM9: =IF($B$31=0,BK9,BH9) -> 36.628323
A10: VIN_min | B10: =VIN_min -> 3 | C10: V | E10: Minimum input voltage | N10: wz_esr | O10: =IF(B31=0,B72,wz_esr/(2*PI())) -> 10150.188 | P10: =COMPLEX(Adc,0) -> 60 | Q10: =IMSUM(COMPLEX(1,0),IMDIV(COMPLEX(0,2*PI()*O10),COMPLEX(wp_lf,0))) -> 1+83,3333333333332i | R10: =IMABS(Q10) -> 83.339333 | S10: =IMARGUMENT(Q10) -> 1.5587969 | T10: =IMSUM(COMPLEX(1,0),IMDIV(COMPLEX(0,2*PI()*O10),COMPLEX(wz_esr,0))) -> 1+i | U10: =IMABS(T10) -> 1.4142136 | V10: =IMARGUMENT(T10) -> 0.78539816 | W10: =IMSUB(COMPLEX(1,0),IMDIV(COMPLEX(0,2*PI()*O10),COMPLEX(wz_rhp,0))) -> 1-1,39508928571429i | X10: =IMABS(W10) -> 1.7164714 | Y10: =IMARGUMENT(W10) -> -0.94888395 | Z10: =IMSUM(COMPLEX(1,0),IMDIV(COMPLEX(0,2*PI()*O10),COMPLEX(Q*(wsl/2),0)),IMDIV(IMPOWER(COMPLEX(0,2*PI()*O10),2),IMPOWER(COMPLEX(wsl/2,0),2))) -> 0,999158968895607+0,372240733027906i | AA10: =IMABS(Z10) -> 1.0662466 | AB10: =IMARGUMENT(Z10) -> 0.35662456 | AC10: =(IMDIV(IMPRODUCT(P10,T10,W10),IMPRODUCT(Q10,Z10))) -> -0,797448632918923-1,4319905634908i | AD10: =20*LOG(IMABS(AC10)) -> 4.2919029 | AE10: =(180/PI())*IMARGUMENT(AC10) -> -119.11261 | AF10: =COMPLEX($B$68,0) -> 326,048966736478 | AG10: =IMSUM(COMPLEX(1,0),IMDIV(COMPLEX(0,2*PI()*O10),COMPLEX(wp_lf_DCM,0))) -> 1+53,5714285714286i | AH10: =IMABS(AG10) -> 53.580761 | AI10: =IMARGUMENT(AG10) -> 1.5521318 | AJ10: =IMSUM(COMPLEX(1,0),IMDIV(COMPLEX(0,2*PI()*O10),COMPLEX(wz1_dcm,0))) -> 1+i | AK10: =IMABS(AJ10) -> 1.4142136 | AL10: =IMARGUMENT(AJ10) -> 0.78539816 | AM10: =IMSUB(COMPLEX(1,0),IMDIV(COMPLEX(0,2*PI()*O10),COMPLEX(wz2_dcm,0))) -> 1-0,165034811704964i | AN10: =IMABS(AM10) -> 1.0135268 | AO10: =IMARGUMENT(AM10) -> -0.16356051 | AP10: =(IMDIV(IMPRODUCT(AF10,AJ10,AM10),IMPRODUCT(AG10))) -> 5,21234802313314-6,99339290617889i | AQ10: =20*LOG(IMABS(AP10)) -> 18.812483 | AR10: =(180/PI())*IMARGUMENT(AP10) -> -53.30193 | AS10: =COMPLEX(Adc_ea,0) -> -0,000100699300699301 | AT10: =COMPLEX(0,2*PI()*O10*wp0_ea) -> 0,0143303571428571i | AU10: =IMABS(AT10) -> 0.014330357 | AV10: =IMARGUMENT(AT10) -> 1.5707963 | AW10: =IMSUM(COMPLEX(1,0),IMDIV(COMPLEX(0,2*PI()*O10),COMPLEX(wp1_ea,0))) -> 1+0,733688001235207i | AX10: =IMABS(AW10) -> 1.2402815 | AY10: =IMARGUMENT(AW10) -> 0.63297943 | AZ10: =IMSUM(COMPLEX(1,0),IMDIV(COMPLEX(0,2*PI()*O10),COMPLEX(wz_ea,0))) -> 1+35,0765306122448i | BA10: =IMABS(AZ10) -> 35.090782 | BB10: =IMARGUMENT(AZ10) -> 1.542295 | BC10: =IMPRODUCT(AS10,IMDIV(AZ10,IMPRODUCT(AT10,AW10))) -> -0,156879133258078+0,12212732941552i | BD10: =20*LOG(IMABS(BC10)) -> -14.031155 | BE10: =(180/PI())*IMARGUMENT(BC10) -> 142.09994 | BF10: =IMPRODUCT(AC10,BC10) -> 0,299988233617517+0,127259166549738i | BG10: =20*LOG(IMABS(BF10)) -> -9.7392523 | BH10: =(180/PI())*IMARGUMENT(BF10) -> 22.98733 | BI10: =IMPRODUCT(AP10,BC10) -> 0,0363757590764867+1,73368756170405i | BJ10: =20*LOG(IMABS(BI10)) -> 4.7813282 | BK10: =(180/PI())*IMARGUMENT(BI10) -> 88.798012 | BL10: =IF($B$31=0,BJ10,BG10) -> -9.7392523 | BM10: =IF($B$31=0,BK10,BH10) -> 22.98733
A11: VIN_nom | B11: =VIN_nom -> 3.7 | C11: V | E11: Nominal input voltage | N11: wp_lf | O11: =IF(B31=0,B70,wp_lf/(2*PI())) -> 121.80225 | P11: =COMPLEX(Adc,0) -> 60 | Q11: =IMSUM(COMPLEX(1,0),IMDIV(COMPLEX(0,2*PI()*O11),COMPLEX(wp_lf,0))) -> 1+i | R11: =IMABS(Q11) -> 1.4142136 | S11: =IMARGUMENT(Q11) -> 0.78539816 | T11: =IMSUM(COMPLEX(1,0),IMDIV(COMPLEX(0,2*PI()*O11),COMPLEX(wz_esr,0))) -> 1+0,012i | U11: =IMABS(T11) -> 1.000072 | V11: =IMARGUMENT(T11) -> 0.011999424 | W11: =IMSUB(COMPLEX(1,0),IMDIV(COMPLEX(0,2*PI()*O11),COMPLEX(wz_rhp,0))) -> 1-0,0167410714285714i | X11: =IMABS(W11) -> 1.0001401 | Y11: =IMARGUMENT(W11) -> -0.016739508 | Z11: =IMSUM(COMPLEX(1,0),IMDIV(COMPLEX(0,2*PI()*O11),COMPLEX(Q*(wsl/2),0)),IMDIV(IMPOWER(COMPLEX(0,2*PI()*O11),2),IMPOWER(COMPLEX(wsl/2,0),2))) -> 0,999999878891521+0,00446688879633487i | AA11: =IMABS(Z11) -> 1.0000099 | AB11: =IMARGUMENT(Z11) -> 0.0044668596 | AC11: =(IMDIV(IMPRODUCT(P11,T11,W11),IMPRODUCT(Q11,Z11))) -> 29,7285361304954-30,2810566608369i | AD11: =20*LOG(IMABS(AC11)) -> 32.554482 | AE11: =(180/PI())*IMARGUMENT(AC11) -> -45.527519 | AF11: =COMPLEX($B$68,0) -> 326,048966736478 | AG11: =IMSUM(COMPLEX(1,0),IMDIV(COMPLEX(0,2*PI()*O11),COMPLEX(wp_lf_DCM,0))) -> 1+0,642857142857143i | AH11: =IMABS(AG11) -> 1.1888084 | AI11: =IMARGUMENT(AG11) -> 0.57133748 | AJ11: =IMSUM(COMPLEX(1,0),IMDIV(COMPLEX(0,2*PI()*O11),COMPLEX(wz1_dcm,0))) -> 1+0,012i | AK11: =IMABS(AJ11) -> 1.000072 | AL11: =IMARGUMENT(AJ11) -> 0.011999424 | AM11: =IMSUB(COMPLEX(1,0),IMDIV(COMPLEX(0,2*PI()*O11),COMPLEX(wz2_dcm,0))) -> 1-0,00198041774045957i | AN11: =IMABS(AM11) -> 1.000002 | AO11: =IMARGUMENT(AM11) -> -0.0019804152 | AP11: =(IMDIV(IMPRODUCT(AF11,AJ11,AM11),IMPRODUCT(AG11))) -> 232,197625911541-146,003027928851i | AQ11: =20*LOG(IMABS(AP11)) -> 48.764062 | AR11: =(180/PI())*IMARGUMENT(AP11) -> -32.161179 | AS11: =COMPLEX(Adc_ea,0) -> -0,000100699300699301 | AT11: =COMPLEX(0,2*PI()*O11*wp0_ea) -> 0,000171964285714286i | AU11: =IMABS(AT11) -> 0.00017196429 | AV11: =IMARGUMENT(AT11) -> 1.5707963 | AW11: =IMSUM(COMPLEX(1,0),IMDIV(COMPLEX(0,2*PI()*O11),COMPLEX(wp1_ea,0))) -> 1+0,00880425601482249i | AX11: =IMABS(AW11) -> 1.0000388 | AY11: =IMARGUMENT(AW11) -> 0.0088040285 | AZ11: =IMSUM(COMPLEX(1,0),IMDIV(COMPLEX(0,2*PI()*O11),COMPLEX(wz_ea,0))) -> 1+0,420918367346938i | BA11: =IMABS(AZ11) -> 1.0849757 | BB11: =IMARGUMENT(AZ11) -> 0.39840839 | BC11: =IMPRODUCT(AS11,IMDIV(AZ11,IMPRODUCT(AT11,AW11))) -> -0,241308164994092+0,587707180520483i | BD11: =20*LOG(IMABS(BC11)) -> -3.9401725 | BE11: =(180/PI())*IMARGUMENT(BC11) -> 112.32269 | BF11: =IMPRODUCT(AC11,BC11) -> 10,622655931711+24,7787403671634i | BG11: =20*LOG(IMABS(BF11)) -> 28.614309 | BH11: =(180/PI())*IMARGUMENT(BF11) -> 66.795167 | BI11: =IMPRODUCT(AP11,BC11) -> 29,7758448668198+171,695934801114i | BJ11: =20*LOG(IMABS(BI11)) -> 44.823889 | BK11: =(180/PI())*IMARGUMENT(BI11) -> 80.161507 | BL11: =IF($B$31=0,BJ11,BG11) -> 28.614309 | BM11: =IF($B$31=0,BK11,BH11) -> 66.795167 | BO11: XOVER SEARCH
